<mujoco model="hand model">
    <compiler angle="radian" meshdir="../../assets/meshes" texturedir="assets" />
    <option integrator="RK4" />

    {{#complete}}
    <asset>
        <mesh file="Segmentation_ZF_DIP.stl" name="ZF-DIP" scale="0.001 0.001 0.001" />
        <mesh file="Segmentation_ZF_PIP.stl" name="ZF-PIP1" scale="0.001 0.001 0.001" />
        <mesh file="zf_mid2.stl" name="ZF-PIP2" scale="0.001 0.001 0.001" />
        <mesh file="zf_mcp.stl" name="ZF-MCP" scale="0.001 0.001 0.001" />
        <mesh file="Segmentation_DAU_Osmetacarpale_1.stl" name="DAU-MCP" scale="0.001 0.001 0.001" />
        <mesh file="Segmentation_DAU_Phalax_proximalis.stl" name="DAU-PIP" scale="0.001 0.001 0.001" />
        <mesh file="Segmentation_DAU_DIP.stl" name="DAU-DIP" scale="0.001 0.001 0.001" />
        <mesh file="backhand.stl" name="BASE" scale="0.001 0.001 0.001" />
        <mesh file="rest.stl" name="OTHER" scale="0.001 0.001 0.001" />
    </asset>
    {{/complete}}

    <worldbody>


        <body name="ZF_MCP" pos="0.17620367646591467 -0.005903444625591753 0.1628356140540645" quat="0.9495917939197236 0.2592798790757723 0.14791767632010086 -0.09575870852740219">


            {{#complete}}
            <geom class="zf" mesh="ZF-MCP" type="mesh" />
            <geom class="base" mesh="BASE" type="mesh" />
            <geom class="other" mesh="OTHER" type="mesh" />
            {{/complete}}


            <body name="DAU_MCP" pos="-0.0009733297722407741 -0.016606395993572436 0.013203568453270123" quat="0.9943462283715698 0.020508983176589547 0.06420367915643692 0.08205392930916784">
      
                {{#complete}}
                <geom class="dau" mesh="DAU-MCP" type="mesh" />
                {{/complete}}

                <joint name="ZF_MCP_to_DAU_CMC" axis="{{dau.cmc.axis}}" limited="true"
                    pos="{{dau.cmc.pos}}" range="{{dau.cmc.range}}" type="hinge" />
                
                <joint axis="{{dau.mcp.axis}}" limited="true" name="DAU_CMC_to_DAU_MCP"
                    pos="{{dau.mcp.pos}}" range="{{dau.mcp.range}}" type="hinge" armature="0.001" />

                <body name="DAU_PIP" pos="0.006597607401319934 0.005692156396961636 -0.004063291682216772" quat="0.9998344657876412 -0.010228438928553777 0.0009345748564418955 -0.015018209948745346">
             
                    {{#complete}}
                    <geom class="dau" mesh="DAU-PIP" type="mesh" />
                    {{/complete}}

                    <joint name="DAU_MCP_to_DAU_PIP" axis="{{dau.pip.axis}}" limited="true" 
                        pos="{{dau.pip.pos}}" range="{{dau.pip.range}}" type="hinge" />
              
                    <body name="DAU_DIP" pos="0.019846615771965104 0.0062637319439134845 4.985729243009019e-05" quat="0.9991378069061835 -0.002240422127798763 0.006912900201265252 -0.04087585020765087">

                        {{#complete}}
                        <geom class="dau" mesh="DAU-DIP" type="mesh" />
                        {{/complete}}

                        <joint name="DAU_PIP_to_DAU_DIP" axis="{{dau.dip.axis}}" limited="true" 
                            pos="{{dau.dip.pos}}" range="{{dau.dip.range}}" type="hinge" />

                        <body name="DAU_TIP"/>

                    </body>
                </body>
            </body>


            <body name="ZF_PIP2" pos="-0.05681330470781501 0.045579181974214705 -0.12097905722243993" quat="0.9545717945947939 -0.22374727893632648 -0.19425296263754305 0.031553615311116466">

                {{#complete}}
                <geom class="zf" mesh="ZF-PIP2" type="mesh" />
                {{/complete}}

                <joint name="ZF_MCP_to_ZF_PIP2" axis="{{zf.mcp.axis}}" limited="true" 
                    pos="{{zf.mcp.pos}}" range="{{zf.mcp.range}}" type="hinge" />

                <body name="ZF_PIP1" pos="0.0035058139319465343 -0.028415907847893287 0.03578303075214987" quat="0.995280924363944 0.08857938205036858 0.03474634812427974 0.019033285708313686">

                    {{#complete}}
                    <geom class="zf" mesh="ZF-PIP1" type="mesh" />
                    {{/complete}}

                    <joint name="ZF_PIP2_to_ZF_PIP1" axis="{{zf.pip.axis}}" limited="true" 
                        pos="{{zf.pip.pos}}" range="{{zf.pip.range}}" type="hinge" />

                    <body name="ZF_DIP" pos="-0.00680048069279826 -0.01349979913849495 0.017965216916995503" quat="0.998934816863429 0.04221477999663421 0.002849840039574148 0.018412561462543154">

                        {{#complete}}
                        <geom class="zf" mesh="ZF-DIP" type="mesh" />
                        {{/complete}}

                        <joint name="ZF_PIP1_to_ZF_DIP" axis="{{zf.dip.axis}}" limited="true" 
                            pos="{{zf.dip.pos}}" range="{{zf.dip.range}}" type="hinge" />

                        <body name="ZF_TIP" />
                    </body>
                </body>
            </body>
        </body>

        {{#complete}}
        <camera name="camera0" pos="0.375 0.069 0.146"
            xyaxes="-0.581 0.814 0.000 -0.114 -0.081 0.990" />
        {{/complete}}
        
    </worldbody>
</mujoco>